<?xml version="1.0"?>
<robot xmlns:xacro="http://www.ros.org/wiki/xacro" name = "thaara_bot">
     
    <material name="blue">
        <color rgba="0 0 1 1"/>
    </material>
    <material name="black">
        <color rgba="0 0 0 1"/>
    </material>
    <material name="red">
        <color rgba="1 0 0 1"/>
    </material>
    <material name="gray">
        <color rgba="0.5 0.5 0.5 1"/>
    </material>
    
    <link name="world"/>

    <link name="base_link">
        <visual>
            <geometry>
                <box size="0.5 0.3 0.1"/>
            </geometry>
            <origin xyz="0.0 0.0 0.05"/>
            <material name="blue"/>
        </visual>
    </link>

    <link name="wheel_fl">
        <visual>
            <!--<geometry>
                <cylinder radius="0.05" length="0.02"/>
            </geometry>-->
                <geometry>
                    <mesh filename="package://robot_description/meshes/Mecanum_wheels_assembly_left_v4.stl" scale="0.002 0.002 0.002"/>
                </geometry>
            <origin xyz="0 0.076 0.0" rpy="1.5708 .0 -1.5708"/>
            <material name="gray"/>
        </visual>
        <collision>
            <geometry>
                    <cylinder radius="0.0" length="0.0"/>
                </geometry>
            <origin xyz="0 0.076 0.0" rpy="1.5708 .0 -1.5708"/>
        </collision>
    </link>

    <link name="wheel_fr">
        <visual>
            <geometry>
                <mesh filename="package://robot_description/meshes/Mecanum_wheels_assembly_left_v4.stl" scale="0.002 0.002 0.002"/>
            </geometry>
            <origin xyz="0 -0.076 0.0" rpy="1.5708 0.0 1.5708"/>
            <material name="gray"/>
        </visual>
    </link>

    <link name="wheel_bl">
        <visual>
            <geometry>
                <mesh filename="package://robot_description/meshes/Mecanum_wheels_assembly_left_v4.stl" scale="0.002 0.002 0.002"/>
            </geometry>
            <origin xyz="0 0.076 0.0" rpy="1.5708 0.0 -1.5708"/>
            <material name="gray"/>
        </visual>
    </link>

    <link name="wheel_br">
        <visual>
            <geometry>
                <mesh filename="package://robot_description/meshes/Mecanum_wheels_assembly_left_v4.stl" scale="0.002 0.002 0.002"/>
            </geometry>
            <origin xyz="0 -0.076 0.0" rpy="1.5708 0.0 1.5708"/>
            <material name="gray"/>
        </visual>
    </link>

    <link name="lidar_stand">
        <visual>
            <geometry>
                <cylinder radius="0.01" length="0.1"/>
            </geometry>
            <origin xyz="0.0 0.0 0.1" rpy="0.0 0.0 0.0"/>
            <material name="gray"/>
        </visual>
    </link>

    <link name="lidar">
        <visual>
            <geometry>
                <cylinder radius="0.03" length="0.02"/>
            </geometry>
            <origin xyz="0.0 0.0 0.015" rpy="0.0 0.0 0.0"/>
            <material name="red"/>
        </visual>
    </link>


    <joint name="joint_wheel_fl" type="continuous">
        <origin xyz="0.2 0.15 0.025" rpy="0.0 0.0 0.0"/>
        <parent link="base_link"/>
        <child link="wheel_fl"/>
        <axis xyz="0.0 1.0 0.0"/>
    </joint>

    <joint name="joint_wheel_fr" type="continuous">
        <origin xyz="0.2 -0.15 0.025" rpy="0.0 0.0 0.0"/>
        <parent link="base_link"/>
        <child link="wheel_fr"/>
        <axis xyz="0.0 1.0 0.0"/>
    </joint>

    <joint name="joint_wheel_bl" type="continuous">
        <origin xyz="-0.2 0.15 0.025" rpy="0.0 0.0 0.0"/>
        <parent link="base_link"/>
        <child link="wheel_bl"/>
        <axis xyz="0.0 1.0 0.0"/>
    </joint>

    <joint name="joint_wheel_br" type="continuous">
        <origin xyz="-0.2 -0.15 0.025" rpy="0.0 0.0 0.0"/>
        <parent link="base_link"/>
        <child link="wheel_br"/>
        <axis xyz="0.0 1.0 0.0"/>
    </joint>

    <joint name="joint_lidar_stand" type="fixed">
        <origin xyz="0.0 0.0 0.05" rpy="0.0 0.0 0.0"/>
        <parent link="base_link"/>
        <child link="lidar_stand"/>
    </joint>

    <joint name="joint_lidar" type="fixed">
        <origin xyz="0.0 0.0 0.05" rpy="0.0 0.0 0.0"/>
        <parent link="lidar_stand"/>
        <child link="lidar"/>
    </joint> 
    
    <joint name="world_to_base" type="fixed">
        <origin xyz="0.0 0.0 0.0" rpy="0.0 0.0 0.0"/>
        <parent link="world"/>
        <child link="base_link"/>
        <axis xyz="0.0 0.0 0.0"/>
    </joint>
    
</robot>
