<?xml version="1.0"?>
<robot xmlns:xacro="http://www.ros.org/wiki/xacro" name="thaara_bot">

  <!-- Properties -->
  <xacro:property name="mesh_scale" value="0.0025"/>
  <xacro:property name="wheel_radius" value="0.125"/>
  <xacro:property name="wheel_x_offset" value="0.400939"/>
  <xacro:property name="wheel_y_offset" value="0.21971"/>
  <xacro:property name="wheel_mass" value="0.34"/>
  <xacro:property name="wheel_length" value="0.05"/>
  <xacro:property name="pos" value="1.5708"/>
  <xacro:property name="base_link_z_offset" value="0.092"/>
  <xacro:property name="zero_mass" value="0.0"/>
  <xacro:property name="zero_inertia" value="0.0"/>

  <!-- Materials -->
  <material name="blue"><color rgba="0 0 1 1"/></material>
  <material name="black"><color rgba="0 0 0 1"/></material>
  <material name="red"><color rgba="1 0 0 1"/></material>
  <material name="beige"><color rgba="0.9608 0.9608 0.8392 1.0"/></material>
  <material name="gray"><color rgba="0.5 0.5 0.5 1"/></material>

  <!-- Inertia for wheels -->
  <xacro:property name="I_wheel" value="${(1.0/12.0)*wheel_mass*(3*wheel_radius*wheel_radius+wheel_length*wheel_length)}"/>
  <xacro:property name="Iz_wheel" value="${0.5*wheel_mass*wheel_radius*wheel_radius}"/>

  <xacro:macro name="inertia_wheel" params="">
    <inertial>
      <origin xyz="0.0 0.0 0.0" rpy="0.0 0.0 0.0"/>
      <mass value="${wheel_mass}"/>
      <inertia ixx="${I_wheel}" ixy="0.0" ixz="0.0" iyy="${I_wheel}" iyz="0.0" izz="${Iz_wheel}"/>
    </inertial>
  </xacro:macro>

  <xacro:include filename="/home/sabin/thaara_mol/src/robot_description/urdf/thaara_control.xacro"/>

  <!-- Wheel and hand macros -->
  <xacro:macro name="wheel_link" params="name rpy">
    <link name="${name}">
      <visual>
        <origin xyz="0 0 0" rpy="${rpy}"/>
        <geometry>
          <mesh filename="package://robot_description/meshes/Simple_wheel_v1.stl" scale="${mesh_scale} ${mesh_scale} ${mesh_scale}"/>
        </geometry>
        <material name="black"/>
      </visual>
      <collision>
        <origin xyz="0 0 0" rpy="${rpy}"/>
        <geometry>
          <mesh filename="package://robot_description/meshes/Simple_wheel_v1.stl" scale="${mesh_scale} ${mesh_scale} ${mesh_scale}"/>
        </geometry>
      </collision>
      <xacro:inertia_wheel/>
    </link>
  </xacro:macro>

  <xacro:macro name="wheel_joint" params="name parent child x y z rpy">
    <joint name="${name}" type="continuous">
      <origin xyz="${x} ${y} ${z}" rpy="${rpy}"/>
      <parent link="${parent}"/>
      <child link="${child}"/>
      <axis xyz="1 0 0"/>
    </joint>
  </xacro:macro>

  <xacro:macro name="hand_link" params="name rpy xyz">
    <link name="${name}">
      <visual>
        <origin xyz="${xyz}" rpy="${rpy}"/>
        <geometry>
          <mesh filename="package://robot_description/meshes/hand_v3.stl" scale="0.0025 0.0025 0.0025"/>
        </geometry>
        <material name="gray"/>
      </visual>
      
      <collision>
        <origin xyz="${xyz}" rpy="${rpy}"/>
        <geometry>
          <mesh filename="package://robot_description/meshes/hand_v3.stl" scale="0.0025 0.0025 0.0025"/>
        </geometry>
      </collision>
  
      <inertial>
        <origin xyz="0 0 0" rpy="0 0 0"/>
        <mass value="0.1"/>
        <inertia ixx="0.001" iyy="0.001" izz="0.001" ixy="0" ixz="0" iyz="0"/>
      </inertial>
    </link>
  </xacro:macro>
  

  <xacro:macro name="hand_joint" params="name parent child x y z rpy">
    <joint name="${name}" type="revolute">
      <origin xyz="${x} ${y} ${z}" rpy="${rpy}"/>
      <parent link="${parent}"/>
      <child link="${child}"/>
      <axis xyz="1 0 0"/>
      <limit lower="-2.35619" upper="0.0" effort="0.0" velocity="1.0"/>
    </joint>
  </xacro:macro>

  <!-- Main Links -->
  <link name="base_link">
    <inertial>
      <origin xyz="0 0 0" rpy="0 0 0"/>
      <mass value="5.0"/>
      <inertia ixx="0.1" ixy="0" ixz="0" iyy="0.1" iyz="0" izz="0.1"/>
    </inertial>
    <visual>
      <origin xyz="0 0 ${base_link_z_offset}" rpy="0 0 0"/>
      <geometry>
        <mesh filename="package://robot_description/meshes/Motor_base_assembeled_rev1.stl" scale="${mesh_scale} ${mesh_scale} ${mesh_scale}"/>
      </geometry>
      <material name="gray"/>
    </visual>
    <collision>
      <origin xyz="0 0 0.125" rpy="0 0 1.5708"/>
      <geometry>
        <mesh filename="package://robot_description/meshes/motor_base_collision.stl" scale="${mesh_scale} ${mesh_scale} ${mesh_scale}"/>
      </geometry>
    </collision>
  </link>

  <link name="outer_shell">
    <inertial>
      <origin xyz="0 0 0" rpy="0 0 0"/>
      <mass value="5.0"/>
      <inertia ixx="0.1" ixy="0" ixz="0" iyy="${zero_inertia}" iyz="0" izz="0.1"/>
    </inertial>
    <visual>
      <origin xyz="0.0 0.0 0.0852485" rpy="0 0 0"/>
      <geometry>
        <mesh filename="package://robot_description/meshes/outer_shell_top.stl" scale="${mesh_scale} ${mesh_scale} ${mesh_scale}"/>
      </geometry>
      <material name="beige"/>
    </visual>
    <collision>
      <origin xyz="0 0 1.038479" rpy="0 0 0"/>
      <geometry>
        <box size="1.095375 0.90424 1.40208"/>
      </geometry>
    </collision>
  </link>

  <!-- Frame workaround for Ignition -->
  <frame name="Shell_to_base" attached_to="base_link">
    <pose relative_to="base_link">0 0 0 0 0 0</pose>
  </frame>

  <!-- Other parts (head, hands, wheels, joints) -->
  <link name="head">
    <inertial><origin xyz="0 0 0"/><mass value="0.2"/><inertia ixx="0.001" ixy="0.0" ixz="0.0" iyy="0.001" iyz="0.0" izz="0.001"/></inertial>
    <visual><origin xyz="0.0 -0.1905 0.03175"/><geometry><mesh filename="package://robot_description/meshes/head_v4.stl" scale="${mesh_scale} ${mesh_scale} ${mesh_scale}"/></geometry></visual>
    <collision><origin xyz="0 0 0"/><geometry><box size="0.05 0.05 0.05"/></geometry></collision>
  </link>

  <xacro:hand_link name="hand_1" xyz="0 0 -0.34925" rpy="${pos} 0 ${pos}"/>
  <xacro:hand_link name="hand_2" xyz="0 0 -0.34925" rpy="${pos} 0 ${-pos}"/>

  <xacro:hand_joint name="hand_1_base" parent="outer_shell" child="hand_1" x="0.55118" y="0" z="1.543685" rpy="0 0 0"/>
  <xacro:hand_joint name="hand_2_base" parent="outer_shell" child="hand_2" x="-0.55118" y="0" z="1.543685" rpy="0 0 0"/>

  <xacro:wheel_link name="wheel_1" rpy="${pos} 0 ${pos}"/>
  <xacro:wheel_link name="wheel_2" rpy="${pos} 0 ${pos}"/>
  <xacro:wheel_link name="wheel_3" rpy="${pos} 0 ${-pos*3}"/>
  <xacro:wheel_link name="wheel_4" rpy="${pos} 0 ${-pos*3}"/>

  <xacro:wheel_joint name="wheel_1_base" parent="base_link" child="wheel_1" x="${wheel_x_offset}" y="${wheel_y_offset}" z="${wheel_radius}" rpy="0 0 0"/>
  <xacro:wheel_joint name="wheel_2_base" parent="base_link" child="wheel_2" x="${wheel_x_offset}" y="-${wheel_y_offset}" z="${wheel_radius}" rpy="0 0 0"/>
  <xacro:wheel_joint name="wheel_3_base" parent="base_link" child="wheel_3" x="-${wheel_x_offset}" y="${wheel_y_offset}" z="${wheel_radius}" rpy="0 0 3.14"/>
  <xacro:wheel_joint name="wheel_4_base" parent="base_link" child="wheel_4" x="-${wheel_x_offset}" y="-${wheel_y_offset}" z="${wheel_radius}" rpy="0 0 3.14"/>

  <joint name="Shell_to_base" type="fixed">
    <origin xyz="0 0 0" rpy="0 0 0"/>
    <parent link="base_link"/>
    <child link="outer_shell"/>
  </joint>

  <joint name="head_to_shell" type="revolute">
    <origin xyz="0 0.0212725 1.739265" rpy="0 0 0"/>
    <parent link="outer_shell"/>
    <child link="head"/>
    <axis xyz="0 0 1"/>
    <limit lower="-1.5708" upper="1.5708" effort="0.0" velocity="1.0"/>
  </joint>

</robot>
